<?xml version="1.0" ?>

<robot xmlns:xacro="http://www.ros.org/wiki/xacro">

  <!--File includes-->
  <xacro:include filename="$(find marco_description)/urdf/deg_to_rad.xacro" />
  <xacro:include filename="$(find marco_description)/urdf/torso/torso.transmission.xacro" />

 <!--Constant parameters-->
  <xacro:property name="torso_max_vel"  value="5.4" />
  <xacro:property name="torso_max_effort"  value="78.0" />
  <xacro:property name="torso_eps"      value="0.02" />

  <xacro:macro name="marco_torso" params="name parent">


  <link name="${name}_fixed_link">
    <inertial>
      <origin rpy="0 0 0" xyz="0 0 0.2" />
      <mass value="7.22876" />
      <inertia ixx="0.04461581" ixy="0" ixz="0"
               iyy="0.004656386" iyz="0"
               izz="0.000459957" />
    </inertial>

    <visual>
      <origin rpy="0 0 0" xyz="0 0 0" />
      <geometry>
        <!-- <box size="0.11 0.07 0.40"/> -->
        <mesh filename="package://marco_description/meshes/torso/lifting_column_inner_body2.stl" scale="0.001 0.001 0.001"/>
      </geometry>
      <material name="LightGrey"/>
    </visual>
    <collision>
      <origin rpy="0 0 0" xyz="0 0 0" />
      <geometry>
        <!-- <box size="0.11 0.07 0.40"/> -->
        <mesh filename="package://marco_description/meshes/torso/lifting_column_inner_body2.stl" scale="0.001 0.001 0.001"/>
      </geometry>
      <material name="LightGrey"/>
    </collision>
 
    <!-- TODO: REMOVE -->
    <!-- Preseries marco boxes on the outside, these should go away in series version -->
    <!-- column motor -->
    <!--
    <visual>
      <origin rpy="${90*deg_to_rad} 0 0" xyz="-0.02 -0.09 0.035" />
      <geometry>
        <cylinder radius="0.035" length="0.09"/>
      </geometry>
      <material name="Yellow"/>
    </visual>
    <collision>
      <origin rpy="${90*deg_to_rad} 0 0" xyz="-0.02 -0.09 0.035" />
      <geometry>
        <cylinder radius="0.035" length="0.09"/>
      </geometry>
      <material name="Yellow"/>
    </collision>
    -->
    <!-- column electronics box -->
    <!--
    <visual>
      <origin rpy="0 0 0" xyz="0.04 -0.175 0.03" />
      <geometry>
        <box size="0.13 0.13 0.06"/>
      </geometry>
      <material name="Yellow"/>
    </visual>
    <collision>
      <origin rpy="0 0 0" xyz="0.04 -0.175 0.03" />
      <geometry>
        <box size="0.13 0.13 0.06"/>
      </geometry>
      <material name="Yellow"/>
    </collision>
    -->
    <!-- cable carrier -->
    <!-- 
    <visual>
      <origin rpy="0 0 0" xyz="0.045 -0.1 0.2" />
      <geometry>
        <box size="0.04 0.10 0.4"/>
      </geometry>
      <material name="Yellow"/>
    </visual>
    <collision>
      <origin rpy="0 0 0" xyz="0.045 -0.1 0.2" />
      <geometry>
        <box size="0.04 0.10 0.4"/>
      </geometry>
      <material name="Yellow"/>
    </collision>
    -->
    <!-- mobile base top cover -->
    <visual>
      <origin rpy="0 0 0" xyz="0.068 0 0.052" />
      <geometry>
        <cylinder radius="0.24" length="0.104"/>
      </geometry>
      <material name="Yellow"/>
    </visual>
    <collision>
      <origin rpy="0 0 0" xyz="0.068 0 -0.12" />
      <geometry>
        <cylinder radius="0.24" length="0.104"/>
      </geometry>
      <material name="Yellow"/>
    </collision>
  </link>

  <joint name="${name}_fixed_joint" type="fixed">
    <origin rpy="0 0 0" xyz="-0.068 0 0.19" />  
    <parent link="${parent}" />
    <child link="${name}_fixed_link" />
    <axis xyz="0 0 0" />
  </joint>

  <link name="${name}_lift_link">
    <inertial>
      <origin rpy="0 0 0" xyz="0 0 0.25157222" /> 
      <mass value="6.5" />

      <inertia ixx="0.016995177" ixy="0" ixz="-0.000000024"
               iyy="0.019054848" iyz="0"
               izz="0.004231158" />
    </inertial>

    <!-- Lifting body -->
    <visual>
      <origin rpy="0 0 0" xyz="0 0 -0.474" />
       <geometry>
        <mesh filename="package://marco_description/meshes/torso/lifting_column_moving_link.stl" scale="0.001 0.001 0.001"/> <!-- 474x170x82 mm -->
       </geometry>
      <material name="White"/>
    </visual>
    <collision>
      <origin rpy="0 0 0" xyz="0 0 -0.474" />
       <geometry>
        <mesh filename="package://marco_description/meshes/torso/lifting_column_moving_link.stl" scale="0.001 0.001 0.001"/> 
       </geometry>
      <material name="White"/>
    </collision>
    <!-- Head pan motor -->
    <visual>
      <origin xyz="0.187 0 0.02" rpy="0 0 0"/>
      <geometry>
        <box size="0.06 0.04 0.04"/>
      </geometry>
      <material name="Grey" />
    </visual>
    <collision>
      <origin xyz="0.187 0 0.02" rpy="0 0 0" />
      <geometry>
        <box size="0.06 0.04 0.04"/>
      </geometry>
      <material name="Grey" />
    </collision>   
    <!-- cable carrier -->
    <!--
    <visual>
      <origin rpy="0 0 0" xyz="0.045 -0.1 -0.4" />
      <geometry>
        <box size="0.04 0.10 0.4"/>
      </geometry>
      <material name="Yellow"/>
    </visual>
    <collision>
      <origin rpy="0 0 0" xyz="0.045 -0.1 -0.4" />
      <geometry>
        <box size="0.04 0.10 0.4"/>
      </geometry>
      <material name="Yellow"/>
    </collision>
    <visual>
      <origin rpy="0 0 0" xyz="0.085 -0.025 -0.25" />
      <geometry>
        <box size="0.025 0.05 0.5"/>
      </geometry>
      <material name="Yellow"/>
    </visual>
  -->
  </link>

  <joint name="${name}_lift_joint" type="prismatic">
    <origin rpy="0 0 0" xyz="0.0 0.0 0.4983" />
    <parent link="${name}_fixed_link" />
    <child link="${name}_lift_link" />
    <axis xyz="0 0 1" />
    <limit effort="2000" lower="0.09" upper="0.35" velocity="0.05" />
    <calibration rising="0.0" />
    <dynamics damping="1000" />

    <safety_controller k_position="20"
                       k_velocity="20"
                       soft_lower_limit="0.09"
                       soft_upper_limit="0.35" />
  </joint>

  <xacro:torso_simple_transmission name="torso_lift" reduction="1.0"/>

  <!-- laptop tray -->
  <link name="laptop_tray_fixed_link">
    <inertial>
      <origin rpy="0 0 0" xyz="0 0 0" />
      <mass value="0.1" />
      <inertia ixx="0.0001" ixy="0.0" ixz="0.0"
               iyy="0.0001" iyz="0.0"
               izz="0.0001" />
    </inertial>

    <visual>
      <origin rpy="0 0 0" xyz="0 0 0" />
      <geometry>
        <box size="0.265 0.33 0.1"/>
      </geometry>
      <material name="LightGrey"/>
    </visual>
    <collision>
      <origin rpy="0 0 0" xyz="0 0 0" />
      <geometry>
        <box size="0.265 0.33 0.1"/>
      </geometry>
      <material name="LightGrey"/>
    </collision>
  </link>

  <joint name="laptop_tray_fixed_joint" type="fixed">
    <origin rpy="0 0 0" xyz="-0.03 0 0.05" />
    <parent link="${name}_lift_link" />
    <child link="laptop_tray_fixed_link" />
    <axis xyz="0 0 0" />
  </joint>

 </xacro:macro>

</robot>
