<sdf version='1.6'>
  <model name='dishwasher'>
    <link name='base_link'>
      <pose frame=''>0 0 0 0 -0 0</pose>
      <inertial>
        <pose frame=''>0.255475 -0.516726 0.405314 0 -0 0</pose>
        <mass>580.455</mass>
        <inertia>
          <ixx>48.972</ixx>
          <ixy>0.0155073</ixy>
          <ixz>-0.0368902</ixz>
          <iyy>62.7974</iyy>
          <iyz>-0.752361</iyz>
          <izz>52.0235</izz>
        </inertia>
      </inertial>
      <collision name='base_link_collision'>
        <pose frame=''>0 0 0 0 -0 0</pose>
        <geometry>
          <mesh>
            <scale>1 1 1</scale>
            <uri>model://dishwasher4/meshes/base_link.STL</uri>
          </mesh>
        </geometry>
      </collision>
      <visual name='base_link_visual'>
        <pose frame=''>0 0 0 0 -0 0</pose>
        <geometry>
          <mesh>
            <scale>1 1 1</scale>
            <uri>model://dishwasher4/meshes/base_link.STL</uri>
          </mesh>
        </geometry>
      </visual>
    </link>
    <link name='door_link'>
      <pose frame=''>0 -0.832302 0.027045 -1.5708 -1.52453 -1.5708</pose>
      <inertial>
        <pose frame=''>0.021615 0.357444 0.255716 0 -0 0</pose>
        <mass>126.317</mass>
        <inertia>
          <ixx>7.49698</ixx>
          <ixy>-0.0125732</ixy>
          <ixz>0.000282137</ixz>
          <iyy>3.12594</iyy>
          <iyz>-0.00237021</iyz>
          <izz>4.41323</izz>
        </inertia>
      </inertial>
      <collision name='door_link_collision'>
        <pose frame=''>0 0 0 0 -0 0</pose>
        <geometry>
          <mesh>
            <scale>1 1 1</scale>
            <uri>model://dishwasher4/meshes/door_link.STL</uri>
          </mesh>
        </geometry>
      </collision>
      <visual name='door_link_visual'>
        <pose frame=''>0 0 0 0 -0 0</pose>
        <geometry>
          <mesh>
            <scale>1 1 1</scale>
            <uri>model://dishwasher4/meshes/door_link.STL</uri>
          </mesh>
        </geometry>
      </visual>
    </link>
    <joint name='door_joint' type='revolute'>
      <child>door_link</child>
      <parent>base_link</parent>
      <axis>
        <xyz>1 -0 -0</xyz>
        <limit>
          <lower>-1e+16</lower>
          <upper>1e+16</upper>
        </limit>
        <dynamics>
          <spring_reference>0</spring_reference>
          <spring_stiffness>0</spring_stiffness>
        </dynamics>
        <use_parent_model_frame>1</use_parent_model_frame>
      </axis>
    </joint>
    <link name='lower_basket_link'>
      <pose frame=''>0.505658 -0.450856 0.135045 1.5708 -0 0</pose>
      <inertial>
        <pose frame=''>-0.25 0.042602 0.193373 0 -0 0</pose>
        <mass>3.49</mass>
        <inertia>
          <ixx>0.0955077</ixx>
          <ixy>8.56464e-17</ixy>
          <ixz>-1.56764e-16</ixz>
          <iyy>0.185033</iyy>
          <iyz>8.11054e-18</iyz>
          <izz>0.0955077</izz>
        </inertia>
      </inertial>
      <collision name='lower_basket_link_collision'>
        <pose frame=''>0 0 0 0 -0 0</pose>
        <geometry>
          <mesh>
            <scale>1 1 1</scale>
            <uri>model://dishwasher4/meshes/lower_basket_link.dae</uri>
          </mesh>
        </geometry>
      </collision>
      <visual name='lower_basket_link_visual'>
        <pose frame=''>0 0 0 0 -0 0</pose>
        <geometry>
          <mesh>
            <scale>1 1 1</scale>
            <uri>model://dishwasher4/meshes/lower_basket_link.dae</uri>
          </mesh>
        </geometry>
      <material> 
        <script>
         <uri>model://dishwasher4/materials/scripts</uri>
         <uri>model://dishwasher4/materials/textures</uri>
          <name>MetalBasket</name>
        </script>
      </material>
      </visual>
    </link>
    <joint name='lower_basket_joint' type='prismatic'>
      <child>lower_basket_link</child>
      <parent>base_link</parent>
      <axis>
        <xyz>0 -1 -0</xyz>
        <limit>
          <lower>0</lower>
          <upper>0</upper>
          <effort>0</effort>
          <velocity>0</velocity>
        </limit>
        <dynamics>
          <spring_reference>0</spring_reference>
          <spring_stiffness>0</spring_stiffness>
        </dynamics>
        <use_parent_model_frame>1</use_parent_model_frame>
      </axis>
    </joint>
    <link name='upper_basket_link'>
      <pose frame=''>0.505658 -0.679426 0.425045 1.5708 -0 0</pose>
      <inertial>
        <pose frame=''>-0.25 0.042602 -0.002466 0 -0 0</pose>
        <mass>3.49</mass>
        <inertia>
          <ixx>0.0955077</ixx>
          <ixy>8.56508e-17</ixy>
          <ixz>-1.56764e-16</ixz>
          <iyy>0.185033</iyy>
          <iyz>2.1346e-18</iyz>
          <izz>0.0955077</izz>
        </inertia>
      </inertial>
      <collision name='upper_basket_link_collision'>
        <pose frame=''>0 0 0 0 -0 0</pose>
        <geometry>
          <mesh>
            <scale>1 1 1</scale>
            <uri>model://dishwasher4/meshes/upper_basket_link.dae</uri>
          </mesh>
        </geometry>
      </collision>
      <visual name='upper_basket_link_visual'>
        <pose frame=''>0 0 0 0 -0 0</pose>
        <geometry>
          <mesh>
            <scale>1 1 1</scale>
            <uri>model://dishwasher4/meshes/upper_basket_link.dae</uri>
          </mesh>
        </geometry>

      <material> 
        <script>
         <uri>model://dishwasher4/materials/scripts</uri>
         <uri>model://dishwasher4/materials/textures</uri>
          <name>MetalBasket</name>
        </script>
      </material>

      </visual>
    </link>
    <joint name='upper_basket_joint' type='prismatic'>
      <child>upper_basket_link</child>
      <parent>base_link</parent>
      <axis>
        <xyz>0 -1 -0</xyz>
        <limit>
          <lower>0</lower>
          <upper>0</upper>
          <effort>0</effort>
          <velocity>0</velocity>
        </limit>
        <dynamics>
          <spring_reference>0</spring_reference>
          <spring_stiffness>0</spring_stiffness>
        </dynamics>
        <use_parent_model_frame>1</use_parent_model_frame>
      </axis>
    </joint>
  </model>
</sdf>
